<?xml version="1.0" encoding="UTF-8"?>
<testsuite errors="0" failures="1" file="classes_user_tests.py" name="classes_user_tests.Test-20190510204708" skipped="0" tests="1" time="0.004" timestamp="2019-05-10T20:47:09">
	<testcase classname="classes_user_tests.Test" file="unittests/classes_user_tests.py" line="13" name="test_get_by_id" time="0.004" timestamp="2019-05-10T20:47:09">
		<failure message="False is not true" type="AssertionError">
<![CDATA[Traceback (most recent call last):
  File "/usr/lib/python3.6/unittest/mock.py", line 1179, in patched
    return func(*args, **keywargs)
  File "/home/matheus/github/eswqa/unittests/classes_user_tests.py", line 16, in test_get_by_id
    self.assertTrue(res)
AssertionError: False is not true
]]>		</failure>
		<system-out>
<![CDATA[<MagicMock name='_select_all_by_userid()' id='140080158994216'>
]]>		</system-out>
		<system-err>
<![CDATA[]]>		</system-err>
	</testcase>
</testsuite>
