<?xml version="1.0" encoding="UTF-8"?>
<testsuite errors="1" failures="0" file="unittest/loader.py" name="unittest.loader._FailedTest-20190510204250" skipped="0" tests="1" time="0.000" timestamp="2019-05-10T20:42:50">
	<testcase classname="unittest.loader._FailedTest" file="/usr/lib/python3.6/unittest/loader.py" line="33" name="classes_user_tests" time="0.000" timestamp="2019-05-10T20:42:50">
		<error message="Failed to import test module: classes_user_tests
Traceback (most recent call last):
  File &quot;/usr/lib/python3.6/unittest/loader.py&quot;, line 153, in loadTestsFromName
    module = __import__(module_name)
  File &quot;/home/matheus/github/eswqa/unittests/classes_user_tests.py&quot;, line 3, in &lt;module&gt;
    from unittest import TestCase, Mock, patch
ImportError: cannot import name 'Mock'
" type="ImportError">
<![CDATA[ImportError: Failed to import test module: classes_user_tests
Traceback (most recent call last):
  File "/usr/lib/python3.6/unittest/loader.py", line 153, in loadTestsFromName
    module = __import__(module_name)
  File "/home/matheus/github/eswqa/unittests/classes_user_tests.py", line 3, in <module>
    from unittest import TestCase, Mock, patch
ImportError: cannot import name 'Mock'

]]>		</error>
		<system-out>
<![CDATA[]]>		</system-out>
		<system-err>
<![CDATA[]]>		</system-err>
	</testcase>
</testsuite>
