<?xml version="1.0" encoding="UTF-8"?>
<testsuite errors="0" failures="1" file="classes_user_tests.py" name="classes_user_tests.Test-20190510205331" skipped="0" tests="1" time="0.003" timestamp="2019-05-10T20:53:32">
	<testcase classname="classes_user_tests.Test" file="unittests/classes_user_tests.py" line="12" name="test_get_by_id" time="0.003" timestamp="2019-05-10T20:53:32">
		<failure message="False is not true" type="AssertionError">
<![CDATA[Traceback (most recent call last):
  File "/usr/lib/python3.6/unittest/mock.py", line 1179, in patched
    return func(*args, **keywargs)
  File "/home/matheus/github/eswqa/unittests/classes_user_tests.py", line 18, in test_get_by_id
    self.assertTrue(res)
AssertionError: False is not true
]]>		</failure>
		<system-out>
<![CDATA[['field1', 'field2']
]]>		</system-out>
		<system-err>
<![CDATA[]]>		</system-err>
	</testcase>
</testsuite>
