<?xml version="1.0" encoding="UTF-8"?>
<testsuite errors="1" failures="0" file="classes_user_tests.py" name="classes_user_tests.Test-20190510204658" skipped="0" tests="1" time="0.004" timestamp="2019-05-10T20:46:58">
	<testcase classname="classes_user_tests.Test" file="unittests/classes_user_tests.py" line="13" name="test_get_by_id" time="0.004" timestamp="2019-05-10T20:46:58">
		<error message="name 'md5' is not defined" type="NameError">
<![CDATA[Traceback (most recent call last):
  File "/usr/lib/python3.6/unittest/mock.py", line 1179, in patched
    return func(*args, **keywargs)
  File "/home/matheus/github/eswqa/unittests/classes_user_tests.py", line 16, in test_get_by_id
    self.assertTrue(md5)
NameError: name 'md5' is not defined
]]>		</error>
		<system-out>
<![CDATA[<MagicMock name='_select_all_by_userid()' id='139994620682136'>
]]>		</system-out>
		<system-err>
<![CDATA[]]>		</system-err>
	</testcase>
</testsuite>
