<?xml version="1.0" encoding="UTF-8"?>
<testsuite errors="1" failures="0" file="classes_user_tests.py" name="classes_user_tests.Test-20190510204504" skipped="0" tests="1" time="0.004" timestamp="2019-05-10T20:45:05">
	<testcase classname="classes_user_tests.Test" file="unittests/classes_user_tests.py" line="13" name="test_get_by_id" time="0.004" timestamp="2019-05-10T20:45:05">
		<error message="No module named 'DB'" type="ModuleNotFoundError">
<![CDATA[Traceback (most recent call last):
  File "/usr/lib/python3.6/unittest/mock.py", line 1171, in patched
    arg = patching.__enter__()
  File "/usr/lib/python3.6/unittest/mock.py", line 1227, in __enter__
    self.target = self.getter()
  File "/usr/lib/python3.6/unittest/mock.py", line 1397, in <lambda>
    getter = lambda: _importer(target)
  File "/usr/lib/python3.6/unittest/mock.py", line 1080, in _importer
    thing = __import__(import_path)
ModuleNotFoundError: No module named 'DB'
]]>		</error>
		<system-out>
<![CDATA[]]>		</system-out>
		<system-err>
<![CDATA[]]>		</system-err>
	</testcase>
</testsuite>
